Workbook
Name L_ACTI_INACTI: Listes!$A$2:$A$3
Name L_CLASSE: Listes!$C$2:$C$4
Name L_FDV: Listes!$B$2:$B$5
Name L_ON: Listes!$D$2:$D$3

Sheet Mode Opératoire
B2: SIMULATEUR DE PRODUCTION
L4: by Loryan
B6: Onglet 1. Base | C6: Dans cet onglet vous allez remplir les infos de votre compte
C7: Attention de ne modifier que les cellules des lignes avec pastille bleues !
B9: Onglet 2. Simulation | C9: Dans cet onglet, vous allez venir remplir les infos de ce que vous souhaitez changer
C10: Attention de ne modifier que les cellules des lignes avec pastille bleues !
B12: Onglet 3. Comparaison | C12: Dans cet onglet, rien besoin de remplir, vous pourrez voir ligne par ligne ce qui est modifié entre la Simulation et la Base
C13: Par défaut, ce qui est en vert est amélioré dans la Simulation
C14: Par défaut, ce qui est en rouge est déprécié dans la Simulation
B16: Onglet 4. Synthèse | C16: Dans cet onglet, idem, rien besoin de remplir, vous aurez une vue un peu plus synthétique de vos gains/pertes
C17: Par défaut, ce qui est en vert est amélioré dans la Simulation
C18: Par défaut, ce qui est en rouge est déprécié dans la Simulation
B20: A retenir | C20: Les arrondis peuvent fausser l'affichage mais les données sont justes, si vous voulez adapter les arrondis à 3 chiffres après la virgules c'est possible
C21: Je vous ai rempli une première planète exemple pour que vous ayez une idée de ce que ça donne une fois rempli :)

Sheet 1. Base
D2: Vitesse de l'Univers ● | E2: 10 | G2: Géologue Actif ● | I2: Oui | K2: Bonus Humain ● | M2: 0.099 | P2: Bonus Métal Global Tech FDV ● | T2: =Y41+Y43+Y47+Y49+Y57+Y59+Y69 -> 0.07942
D3: Classe choisie ● | E3: Explorateur | G3: Full Offi Actif ● | I3: Oui | K3: Bonus Méca ● | M3: 0.097 | P3: Bonus Cristal Global tech FDV ● | T3: =Y41+Y43+Y47+Y49+Y69 -> 0.05214
G4: Classe Marchand ● | I4: Oui | K4: Bonus Rocta ● | M4: 0.1 | P4: Bonus Deut Global Tech FDV ● | T4: =Y41+Y43+Y45+Y47+Y49+Y53+Y69 -> 0.08646
K5: Bonus Kaelesh ● | M5: 0.098 | P5: Bonus Collecteur ● | T5: =Y65 -> 0
B6: ● | C6: Remplir la ligne
B7: ● | C7: Ne pas toucher la ligne (formules)
D8: N° de Planète | E8: Planète 1 | F8: Planète 2 | G8: Planète 3 | H8: Planète 4 | I8: Planète 5 | J8: Planète 6 | K8: Planète 7 | L8: Planète 8 | M8: Planète 9 | N8: Planète 10 | O8: Planète 11 | P8: Planète 12 | Q8: Planète 13 | R8: Planète 14 | S8: Planète 15 | T8: Planète 16 | U8: Planète 17 | V8: Planète 18 | W8: Planète 19 | X8: Planète 20 | Y8: Total
B9: ● | C9: Infos de Base | D9: Nom de Planète | E9: Birgitte
B10: ● | D10: Coordonnées de la Planète | E10: 3:198:15
B11: ● | D11: Position de la Planète | E11: =--MID(E10,SEARCH(":",E10,SEARCH(":",E10)+1)+1,LEN(E10)) -> 15
B12: ● | D12: Température Max | E12: -130
B13: ● | D13: Race Choisie | E13: Rocta
B14: ● | D14: Nb Max de foreuses | E14: =IF(AND($E$3="Collecteur",$I$2="Oui"),(E17+E18+E19)*8*1.1,(E17+E18+E19)*8) -> 1040 | F14: =IF(AND($E$3="Collecteur",$I$2="Oui"),(F17+F18+F19)*8*1.1,(F17+F18+F19)*8) -> 0 | G14: =IF(AND($E$3="Collecteur",$I$2="Oui"),(G17+G18+G19)*8*1.1,(G17+G18+G19)*8) -> 0 | H14: =IF(AND($E$3="Collecteur",$I$2="Oui"),(H17+H18+H19)*8*1.1,(H17+H18+H19)*8) -> 0 | I14: =IF(AND($E$3="Collecteur",$I$2="Oui"),(I17+I18+I19)*8*1.1,(I17+I18+I19)*8) -> 0 | J14: =IF(AND($E$3="Collecteur",$I$2="Oui"),(J17+J18+J19)*8*1.1,(J17+J18+J19)*8) -> 0 | K14: =IF(AND($E$3="Collecteur",$I$2="Oui"),(K17+K18+K19)*8*1.1,(K17+K18+K19)*8) -> 0 | L14: =IF(AND($E$3="Collecteur",$I$2="Oui"),(L17+L18+L19)*8*1.1,(L17+L18+L19)*8) -> 0 | ... X14: =IF(AND($E$3="Collecteur",$I$2="Oui"),(X17+X18+X19)*8*1.1,(X17+X18+X19)*8) -> 0
B15: ● | D15: Alerte Foreuse | E15: =IF(E28>=E14,"OK","UP") -> OK | F15: =IF(F28>=F14,"OK","UP") -> OK | G15: =IF(G28>=G14,"OK","UP") -> OK | H15: =IF(H28>=H14,"OK","UP") -> OK | I15: =IF(I28>=I14,"OK","UP") -> OK | J15: =IF(J28>=J14,"OK","UP") -> OK | K15: =IF(K28>=K14,"OK","UP") -> OK | L15: =IF(L28>=L14,"OK","UP") -> OK | ... X15: =IF(X28>=X14,"OK","UP") -> OK
B17: ● | C17: Infos Mines & Bats Prod FDV | D17: Mine de Métal | E17: 48 | Y17: =SUM(E17:X17) -> 48
B18: ● | D18: Mine de Cristal | E18: 39 | Y18: =SUM(E18:X18) -> 39
B19: ● | D19: Mine de Deut | E19: 43 | Y19: =SUM(E19:X19) -> 43
B20: ● | D20: Centrale Fusion | E20: 24 | Y20: =SUM(E20:X20) -> 24
B21: ● | D21: Fusion Magmatique (Rocta) (Mét 2%) | E21: 23 | Y21: =SUM(E21:X21) -> 23
B22: ● | D22: Raffinerie de Cristaux (Rocta) (Cri 2%) | E22: 13 | Y22: =SUM(E22:X22) -> 13
B23: ● | D23: Synto de Deut (Rocta) (Deut 2%) | E23: 17 | Y23: =SUM(E23:X23) -> 17
B24: ● | D24: Fusion à haute énergie (Humains) (Mét 1,5%) | E24: 0 | Y24: =SUM(E24:X24) -> 0
B25: ● | D25: Extraction par fusion (Humains) (Cri 1,5%) | E25: 0 | Y25: =SUM(E25:X25) -> 0
B26: ● | D26: Extraction par fusion (Humains) (Deut 1%) | E26: 0 | Y26: =SUM(E26:X26) -> 0
B27: ● | D27: Synthétiseur à haut rendement (Méca) (Deut 2%) | E27: 0 | Y27: =SUM(E27:X27) -> 0
B28: ● | D28: Nombre de Foreuses | E28: 1200 | Y28: =SUM(E28:X28) -> 1200
B29: ● | D29: Tech Plasma | E29: 23 | Y29: =AVERAGE(E29:X29) -> 23
B31: ● | C31: Objets | D31: % Bonus Objet Mét | E31: 0
B32: ● | D32: % Bonus Objet Cri | E32: 0
B33: ● | D33: % Bonus Objet Deut | E33: 0.4
B35: ● | C35: Bat Boost Tech FDV | D35: Métro (Humain) (0,5%) | E35: 0 | Y35: =SUM(E35:X35) -> 0
B36: ● | D36: Transfo Hyper (Méca) (0,3%) | E36: 0 | Y36: =SUM(E36:X36) -> 0
B37: ● | D37: Prod de Puces (Méca) (0,4%) | E37: 0 | Y37: =SUM(E37:X37) -> 0
B38: ● | D38: Labo de Clonage (Kaelesh) (0,25%) | E38: 0 | Y38: =SUM(E38:X38) -> 0
B40: ● | C40: Actif | D40: 1-2 Humain (Trio) (0,06%) | E40: 19 | Y40: =SUM(E40:X40) -> 19
B41: ● | D41: Bonus Mét + Cri + Deut | E41: =IF($C$40="Inactif",0,IF(E13="Rocta",E40*0.06%+E40*0.06%*$M$4,IF(E13="Humains",E40*0.06%+E40*0.06%*$M$2+E40*0.06%*E35*0.5%,IF(E13="Méca",E40*0.06%+E40*0.06%*$M$3+E40*0.06%*E36*0.3%+E40*0.06%*E37*0.4%,E40*0.06%+E40*0.06%*$M$5+E40*0.06%*E38*0.25%)))) -> 0.01254 | F41: =IF($C$40="Inactif",0,IF(F13="Rocta",F40*0.06%+F40*0.06%*$M$4,IF(F13="Humains",F40*0.06%+F40*0.06%*$M$2+F40*0.06%*F35*0.5%,IF(F13="Méca",F40*0.06%+F40*0.06%*$M$3+F40*0.06%*F36*0.3%+F40*0.06%*F37*0.4%,F40*0.06%+F40*0.06%*$M$5+F40*0.06%*F38*0.25%)))) -> 0 | G41: =IF($C$40="Inactif",0,IF(G13="Rocta",G40*0.06%+G40*0.06%*$M$4,IF(G13="Humains",G40*0.06%+G40*0.06%*$M$2+G40*0.06%*G35*0.5%,IF(G13="Méca",G40*0.06%+G40*0.06%*$M$3+G40*0.06%*G36*0.3%+G40*0.06%*G37*0.4%,G40*0.06%+G40*0.06%*$M$5+G40*0.06%*G38*0.25%)))) -> 0 | H41: =IF($C$40="Inactif",0,IF(H13="Rocta",H40*0.06%+H40*0.06%*$M$4,IF(H13="Humains",H40*0.06%+H40*0.06%*$M$2+H40*0.06%*H35*0.5%,IF(H13="Méca",H40*0.06%+H40*0.06%*$M$3+H40*0.06%*H36*0.3%+H40*0.06%*H37*0.4%,H40*0.06%+H40*0.06%*$M$5+H40*0.06%*H38*0.25%)))) -> 0 | I41: =IF($C$40="Inactif",0,IF(I13="Rocta",I40*0.06%+I40*0.06%*$M$4,IF(I13="Humains",I40*0.06%+I40*0.06%*$M$2+I40*0.06%*I35*0.5%,IF(I13="Méca",I40*0.06%+I40*0.06%*$M$3+I40*0.06%*I36*0.3%+I40*0.06%*I37*0.4%,I40*0.06%+I40*0.06%*$M$5+I40*0.06%*I38*0.25%)))) -> 0 | J41: =IF($C$40="Inactif",0,IF(J13="Rocta",J40*0.06%+J40*0.06%*$M$4,IF(J13="Humains",J40*0.06%+J40*0.06%*$M$2+J40*0.06%*J35*0.5%,IF(J13="Méca",J40*0.06%+J40*0.06%*$M$3+J40*0.06%*J36*0.3%+J40*0.06%*J37*0.4%,J40*0.06%+J40*0.06%*$M$5+J40*0.06%*J38*0.25%)))) -> 0 | K41: =IF($C$40="Inactif",0,IF(K13="Rocta",K40*0.06%+K40*0.06%*$M$4,IF(K13="Humains",K40*0.06%+K40*0.06%*$M$2+K40*0.06%*K35*0.5%,IF(K13="Méca",K40*0.06%+K40*0.06%*$M$3+K40*0.06%*K36*0.3%+K40*0.06%*K37*0.4%,K40*0.06%+K40*0.06%*$M$5+K40*0.06%*K38*0.25%)))) -> 0 | L41: =IF($C$40="Inactif",0,IF(L13="Rocta",L40*0.06%+L40*0.06%*$M$4,IF(L13="Humains",L40*0.06%+L40*0.06%*$M$2+L40*0.06%*L35*0.5%,IF(L13="Méca",L40*0.06%+L40*0.06%*$M$3+L40*0.06%*L36*0.3%+L40*0.06%*L37*0.4%,L40*0.06%+L40*0.06%*$M$5+L40*0.06%*L38*0.25%)))) -> 0 | ... X41: =IF($C$40="Inactif",0,IF(X13="Rocta",X40*0.06%+X40*0.06%*$M$4,IF(X13="Humains",X40*0.06%+X40*0.06%*$M$2+X40*0.06%*X35*0.5%,IF(X13="Méca",X40*0.06%+X40*0.06%*$M$3+X40*0.06%*X36*0.3%+X40*0.06%*X37*0.4%,X40*0.06%+X40*0.06%*$M$5+X40*0.06%*X38*0.25%)))) -> 0 | Y41: =SUM(E41:X41) -> 0.01254
B42: ● | C42: Actif | D42: 2-2 Humain (Trio) (0,06%) | E42: 16 | Y42: =SUM(E42:X42) -> 16
B43: ● | D43: Bonus Mét + Cri + Deut | E43: =IF($C$42="Inactif",0,IF(E13="Rocta",E42*0.06%+E42*0.06%*$M$4,IF(E13="Humains",E42*0.06%+E42*0.06%*$M$2+E42*0.06%*E35*0.5%,IF(E13="Méca",E42*0.06%+E42*0.06%*$M$3+E42*0.06%*E36*0.3%+E42*0.06%*E37*0.4%,E42*0.06%+E42*0.06%*$M$5+E42*0.06%*E38*0.25%)))) -> 0.01056 | F43: =IF($C$42="Inactif",0,IF(F13="Rocta",F42*0.06%+F42*0.06%*$M$4,IF(F13="Humains",F42*0.06%+F42*0.06%*$M$2+F42*0.06%*F35*0.5%,IF(F13="Méca",F42*0.06%+F42*0.06%*$M$3+F42*0.06%*F36*0.3%+F42*0.06%*F37*0.4%,F42*0.06%+F42*0.06%*$M$5+F42*0.06%*F38*0.25%)))) -> 0 | G43: =IF($C$42="Inactif",0,IF(G13="Rocta",G42*0.06%+G42*0.06%*$M$4,IF(G13="Humains",G42*0.06%+G42*0.06%*$M$2+G42*0.06%*G35*0.5%,IF(G13="Méca",G42*0.06%+G42*0.06%*$M$3+G42*0.06%*G36*0.3%+G42*0.06%*G37*0.4%,G42*0.06%+G42*0.06%*$M$5+G42*0.06%*G38*0.25%)))) -> 0 | H43: =IF($C$42="Inactif",0,IF(H13="Rocta",H42*0.06%+H42*0.06%*$M$4,IF(H13="Humains",H42*0.06%+H42*0.06%*$M$2+H42*0.06%*H35*0.5%,IF(H13="Méca",H42*0.06%+H42*0.06%*$M$3+H42*0.06%*H36*0.3%+H42*0.06%*H37*0.4%,H42*0.06%+H42*0.06%*$M$5+H42*0.06%*H38*0.25%)))) -> 0 | I43: =IF($C$42="Inactif",0,IF(I13="Rocta",I42*0.06%+I42*0.06%*$M$4,IF(I13="Humains",I42*0.06%+I42*0.06%*$M$2+I42*0.06%*I35*0.5%,IF(I13="Méca",I42*0.06%+I42*0.06%*$M$3+I42*0.06%*I36*0.3%+I42*0.06%*I37*0.4%,I42*0.06%+I42*0.06%*$M$5+I42*0.06%*I38*0.25%)))) -> 0 | J43: =IF($C$42="Inactif",0,IF(J13="Rocta",J42*0.06%+J42*0.06%*$M$4,IF(J13="Humains",J42*0.06%+J42*0.06%*$M$2+J42*0.06%*J35*0.5%,IF(J13="Méca",J42*0.06%+J42*0.06%*$M$3+J42*0.06%*J36*0.3%+J42*0.06%*J37*0.4%,J42*0.06%+J42*0.06%*$M$5+J42*0.06%*J38*0.25%)))) -> 0 | K43: =IF($C$42="Inactif",0,IF(K13="Rocta",K42*0.06%+K42*0.06%*$M$4,IF(K13="Humains",K42*0.06%+K42*0.06%*$M$2+K42*0.06%*K35*0.5%,IF(K13="Méca",K42*0.06%+K42*0.06%*$M$3+K42*0.06%*K36*0.3%+K42*0.06%*K37*0.4%,K42*0.06%+K42*0.06%*$M$5+K42*0.06%*K38*0.25%)))) -> 0 | L43: =IF($C$42="Inactif",0,IF(L13="Rocta",L42*0.06%+L42*0.06%*$M$4,IF(L13="Humains",L42*0.06%+L42*0.06%*$M$2+L42*0.06%*L35*0.5%,IF(L13="Méca",L42*0.06%+L42*0.06%*$M$3+L42*0.06%*L36*0.3%+L42*0.06%*L37*0.4%,L42*0.06%+L42*0.06%*$M$5+L42*0.06%*L38*0.25%)))) -> 0 | ... X43: =IF($C$42="Inactif",0,IF(X13="Rocta",X42*0.06%+X42*0.06%*$M$4,IF(X13="Humains",X42*0.06%+X42*0.06%*$M$2+X42*0.06%*X35*0.5%,IF(X13="Méca",X42*0.06%+X42*0.06%*$M$3+X42*0.06%*X36*0.3%+X42*0.06%*X37*0.4%,X42*0.06%+X42*0.06%*$M$5+X42*0.06%*X38*0.25%)))) -> 0 | Y43: =SUM(E43:X43) -> 0.01056
B44: ● | C44: Actif | D44: 1-1 Méca (Deut) (0,08%) | E44: 20 | Y44: =SUM(E44:X44) -> 20
B45: ● | D45: Bonus Deut | E45: =IF($C$44="Inactif",0,IF(E13="Rocta",E44*0.08%+E44*0.08%*$M$4,IF(E13="Humains",E44*0.08%+E44*0.08%*$M$2+E44*0.08%*E35*0.5%,IF(E13="Méca",E44*0.08%+E44*0.08%*$M$3+E44*0.08%*E36*0.3%+E44*0.08%*E37*0.4%,E44*0.08%+E44*0.08%*$M$5+E44*0.08%*E38*0.25%)))) -> 0.0176 | F45: =IF($C$44="Inactif",0,IF(F13="Rocta",F44*0.08%+F44*0.08%*$M$4,IF(F13="Humains",F44*0.08%+F44*0.08%*$M$2+F44*0.08%*F35*0.5%,IF(F13="Méca",F44*0.08%+F44*0.08%*$M$3+F44*0.08%*F36*0.3%+F44*0.08%*F37*0.4%,F44*0.08%+F44*0.08%*$M$5+F44*0.08%*F38*0.25%)))) -> 0 | G45: =IF($C$44="Inactif",0,IF(G13="Rocta",G44*0.08%+G44*0.08%*$M$4,IF(G13="Humains",G44*0.08%+G44*0.08%*$M$2+G44*0.08%*G35*0.5%,IF(G13="Méca",G44*0.08%+G44*0.08%*$M$3+G44*0.08%*G36*0.3%+G44*0.08%*G37*0.4%,G44*0.08%+G44*0.08%*$M$5+G44*0.08%*G38*0.25%)))) -> 0 | H45: =IF($C$44="Inactif",0,IF(H13="Rocta",H44*0.08%+H44*0.08%*$M$4,IF(H13="Humains",H44*0.08%+H44*0.08%*$M$2+H44*0.08%*H35*0.5%,IF(H13="Méca",H44*0.08%+H44*0.08%*$M$3+H44*0.08%*H36*0.3%+H44*0.08%*H37*0.4%,H44*0.08%+H44*0.08%*$M$5+H44*0.08%*H38*0.25%)))) -> 0 | I45: =IF($C$44="Inactif",0,IF(I13="Rocta",I44*0.08%+I44*0.08%*$M$4,IF(I13="Humains",I44*0.08%+I44*0.08%*$M$2+I44*0.08%*I35*0.5%,IF(I13="Méca",I44*0.08%+I44*0.08%*$M$3+I44*0.08%*I36*0.3%+I44*0.08%*I37*0.4%,I44*0.08%+I44*0.08%*$M$5+I44*0.08%*I38*0.25%)))) -> 0 | J45: =IF($C$44="Inactif",0,IF(J13="Rocta",J44*0.08%+J44*0.08%*$M$4,IF(J13="Humains",J44*0.08%+J44*0.08%*$M$2+J44*0.08%*J35*0.5%,IF(J13="Méca",J44*0.08%+J44*0.08%*$M$3+J44*0.08%*J36*0.3%+J44*0.08%*J37*0.4%,J44*0.08%+J44*0.08%*$M$5+J44*0.08%*J38*0.25%)))) -> 0 | K45: =IF($C$44="Inactif",0,IF(K13="Rocta",K44*0.08%+K44*0.08%*$M$4,IF(K13="Humains",K44*0.08%+K44*0.08%*$M$2+K44*0.08%*K35*0.5%,IF(K13="Méca",K44*0.08%+K44*0.08%*$M$3+K44*0.08%*K36*0.3%+K44*0.08%*K37*0.4%,K44*0.08%+K44*0.08%*$M$5+K44*0.08%*K38*0.25%)))) -> 0 | L45: =IF($C$44="Inactif",0,IF(L13="Rocta",L44*0.08%+L44*0.08%*$M$4,IF(L13="Humains",L44*0.08%+L44*0.08%*$M$2+L44*0.08%*L35*0.5%,IF(L13="Méca",L44*0.08%+L44*0.08%*$M$3+L44*0.08%*L36*0.3%+L44*0.08%*L37*0.4%,L44*0.08%+L44*0.08%*$M$5+L44*0.08%*L38*0.25%)))) -> 0 | ... X45: =IF($C$44="Inactif",0,IF(X13="Rocta",X44*0.08%+X44*0.08%*$M$4,IF(X13="Humains",X44*0.08%+X44*0.08%*$M$2+X44*0.08%*X35*0.5%,IF(X13="Méca",X44*0.08%+X44*0.08%*$M$3+X44*0.08%*X36*0.3%+X44*0.08%*X37*0.4%,X44*0.08%+X44*0.08%*$M$5+X44*0.08%*X38*0.25%)))) -> 0 | Y45: =SUM(E45:X45) -> 0.0176
...

Sheet 2. Simulation
D2: Vitesse de l'Univers ● | E2: 10 | G2: Géologue Actif ● | I2: Oui | K2: Bonus Humain ● | M2: 0.099 | P2: Bonus Métal Global Tech FDV ● | T2: =Y41+Y43+Y47+Y49+Y57+Y59+Y69 -> 0.08664
D3: Classe choisie ● | E3: Explorateur | G3: Full Offi Actif ● | I3: Oui | K3: Bonus Méca ● | M3: 0.097 | P3: Bonus Cristal Global tech FDV ● | T3: =Y41+Y43+Y47+Y49+Y69 -> 0.05688
G4: Classe Marchand ● | I4: Oui | K4: Bonus Rocta ● | M4: 0.1 | P4: Bonus Deut Global Tech FDV ● | T4: =Y41+Y43+Y45+Y47+Y49+Y53+Y69 -> 0.09432
K5: Bonus Kaelesh ● | M5: 0.098 | P5: Bonus Collecteur ● | T5: =Y65 -> 0
B6: ● | C6: Remplir la ligne
B7: ● | C7: Ne pas toucher la ligne (formules)
D8: N° de Planète | E8: Planète 1 | F8: Planète 2 | G8: Planète 3 | H8: Planète 4 | I8: Planète 5 | J8: Planète 6 | K8: Planète 7 | L8: Planète 8 | M8: Planète 9 | N8: Planète 10 | O8: Planète 11 | P8: Planète 12 | Q8: Planète 13 | R8: Planète 14 | S8: Planète 15 | T8: Planète 16 | U8: Planète 17 | V8: Planète 18 | W8: Planète 19 | X8: Planète 20 | Y8: Total
B9: ● | C9: Infos de Base | D9: Nom de Planète | E9: Birgitte
B10: ● | D10: Coordonnées de la Planète | E10: 3:198:15
B11: ● | D11: Position de la Planète | E11: =--MID(E10,SEARCH(":",E10,SEARCH(":",E10)+1)+1,LEN(E10)) -> 15
B12: ● | D12: Température Max | E12: -130
B13: ● | D13: Race Choisie | E13: Méca
B14: ● | D14: Nb Max de foreuses | E14: =IF(AND($E$3="Collecteur",$I$2="Oui"),(E17+E18+E19)*8*1.1,(E17+E18+E19)*8) -> 1040 | F14: =IF(AND($E$3="Collecteur",$I$2="Oui"),(F17+F18+F19)*8*1.1,(F17+F18+F19)*8) -> 0 | G14: =IF(AND($E$3="Collecteur",$I$2="Oui"),(G17+G18+G19)*8*1.1,(G17+G18+G19)*8) -> 0 | H14: =IF(AND($E$3="Collecteur",$I$2="Oui"),(H17+H18+H19)*8*1.1,(H17+H18+H19)*8) -> 0 | I14: =IF(AND($E$3="Collecteur",$I$2="Oui"),(I17+I18+I19)*8*1.1,(I17+I18+I19)*8) -> 0 | J14: =IF(AND($E$3="Collecteur",$I$2="Oui"),(J17+J18+J19)*8*1.1,(J17+J18+J19)*8) -> 0 | K14: =IF(AND($E$3="Collecteur",$I$2="Oui"),(K17+K18+K19)*8*1.1,(K17+K18+K19)*8) -> 0 | L14: =IF(AND($E$3="Collecteur",$I$2="Oui"),(L17+L18+L19)*8*1.1,(L17+L18+L19)*8) -> 0 | ... X14: =IF(AND($E$3="Collecteur",$I$2="Oui"),(X17+X18+X19)*8*1.1,(X17+X18+X19)*8) -> 0
B15: ● | D15: Alerte Foreuse | E15: =IF(E28>=E14,"OK","UP") -> OK | F15: =IF(F28>=F14,"OK","UP") -> OK | G15: =IF(G28>=G14,"OK","UP") -> OK | H15: =IF(H28>=H14,"OK","UP") -> OK | I15: =IF(I28>=I14,"OK","UP") -> OK | J15: =IF(J28>=J14,"OK","UP") -> OK | K15: =IF(K28>=K14,"OK","UP") -> OK | L15: =IF(L28>=L14,"OK","UP") -> OK | ... X15: =IF(X28>=X14,"OK","UP") -> OK
B17: ● | C17: Infos Mines & Bats Prod FDV | D17: Mine de Métal | E17: 48 | Y17: =SUM(E17:X17) -> 48
B18: ● | D18: Mine de Cristal | E18: 39 | Y18: =SUM(E18:X18) -> 39
B19: ● | D19: Mine de Deut | E19: 43 | Y19: =SUM(E19:X19) -> 43
B20: ● | D20: Centrale Fusion | E20: 24 | Y20: =SUM(E20:X20) -> 24
B21: ● | D21: Fusion Magmatique (Rocta) (Mét 2%) | E21: 23 | Y21: =SUM(E21:X21) -> 23
B22: ● | D22: Raffinerie de Cristaux (Rocta) (Cri 2%) | E22: 13 | Y22: =SUM(E22:X22) -> 13
B23: ● | D23: Synto de Deut (Rocta) (Deut 2%) | E23: 17 | Y23: =SUM(E23:X23) -> 17
B24: ● | D24: Fusion à haute énergie (Humains) (Mét 1,5%) | E24: 0 | Y24: =SUM(E24:X24) -> 0
B25: ● | D25: Extraction par fusion (Humains) (Cri 1,5%) | E25: 0 | Y25: =SUM(E25:X25) -> 0
B26: ● | D26: Extraction par fusion (Humains) (Deut 1%) | E26: 0 | Y26: =SUM(E26:X26) -> 0
B27: ● | D27: Synthétiseur à haut rendement (Méca) (Deut 2%) | E27: 15 | Y27: =SUM(E27:X27) -> 15
B28: ● | D28: Nombre de Foreuses | E28: 1200 | Y28: =SUM(E28:X28) -> 1200
B29: ● | D29: Tech Plasma | E29: 23 | Y29: =AVERAGE(E29:X29) -> 23
B31: ● | C31: Objets | D31: % Bonus Objet Mét | E31: 0
B32: ● | D32: % Bonus Objet Cri | E32: 0
B33: ● | D33: % Bonus Objet Deut | E33: 0.4
B35: ● | C35: Bat Boost Tech FDV | D35: Métro (Humain) (0,5%) | E35: 0 | Y35: =SUM(E35:X35) -> 0
B36: ● | D36: Transfo Hyper (Méca) (0,3%) | E36: 17 | Y36: =SUM(E36:X36) -> 17
B37: ● | D37: Prod de Puces (Méca) (0,4%) | E37: 13 | Y37: =SUM(E37:X37) -> 13
B38: ● | D38: Labo de Clonage (Kaelesh) (0,25%) | E38: 0 | Y38: =SUM(E38:X38) -> 0
B40: ● | C40: Actif | D40: 1-2 Humain (Trio) (0,06%) | E40: 19 | Y40: =SUM(E40:X40) -> 19
B41: ● | D41: Bonus Mét + Cri + Deut | E41: =IF($C$40="Inactif",0,IF(E13="Rocta",E40*0.06%+E40*0.06%*$M$4,IF(E13="Humains",E40*0.06%+E40*0.06%*$M$2+E40*0.06%*E35*0.5%,IF(E13="Méca",E40*0.06%+E40*0.06%*$M$3+E40*0.06%*E36*0.3%+E40*0.06%*E37*0.4%,E40*0.06%+E40*0.06%*$M$5+E40*0.06%*E38*0.25%)))) -> 0.01368 | F41: =IF($C$40="Inactif",0,IF(F13="Rocta",F40*0.06%+F40*0.06%*$M$4,IF(F13="Humains",F40*0.06%+F40*0.06%*$M$2+F40*0.06%*F35*0.5%,IF(F13="Méca",F40*0.06%+F40*0.06%*$M$3+F40*0.06%*F36*0.3%+F40*0.06%*F37*0.4%,F40*0.06%+F40*0.06%*$M$5+F40*0.06%*F38*0.25%)))) -> 0 | G41: =IF($C$40="Inactif",0,IF(G13="Rocta",G40*0.06%+G40*0.06%*$M$4,IF(G13="Humains",G40*0.06%+G40*0.06%*$M$2+G40*0.06%*G35*0.5%,IF(G13="Méca",G40*0.06%+G40*0.06%*$M$3+G40*0.06%*G36*0.3%+G40*0.06%*G37*0.4%,G40*0.06%+G40*0.06%*$M$5+G40*0.06%*G38*0.25%)))) -> 0 | H41: =IF($C$40="Inactif",0,IF(H13="Rocta",H40*0.06%+H40*0.06%*$M$4,IF(H13="Humains",H40*0.06%+H40*0.06%*$M$2+H40*0.06%*H35*0.5%,IF(H13="Méca",H40*0.06%+H40*0.06%*$M$3+H40*0.06%*H36*0.3%+H40*0.06%*H37*0.4%,H40*0.06%+H40*0.06%*$M$5+H40*0.06%*H38*0.25%)))) -> 0 | I41: =IF($C$40="Inactif",0,IF(I13="Rocta",I40*0.06%+I40*0.06%*$M$4,IF(I13="Humains",I40*0.06%+I40*0.06%*$M$2+I40*0.06%*I35*0.5%,IF(I13="Méca",I40*0.06%+I40*0.06%*$M$3+I40*0.06%*I36*0.3%+I40*0.06%*I37*0.4%,I40*0.06%+I40*0.06%*$M$5+I40*0.06%*I38*0.25%)))) -> 0 | J41: =IF($C$40="Inactif",0,IF(J13="Rocta",J40*0.06%+J40*0.06%*$M$4,IF(J13="Humains",J40*0.06%+J40*0.06%*$M$2+J40*0.06%*J35*0.5%,IF(J13="Méca",J40*0.06%+J40*0.06%*$M$3+J40*0.06%*J36*0.3%+J40*0.06%*J37*0.4%,J40*0.06%+J40*0.06%*$M$5+J40*0.06%*J38*0.25%)))) -> 0 | K41: =IF($C$40="Inactif",0,IF(K13="Rocta",K40*0.06%+K40*0.06%*$M$4,IF(K13="Humains",K40*0.06%+K40*0.06%*$M$2+K40*0.06%*K35*0.5%,IF(K13="Méca",K40*0.06%+K40*0.06%*$M$3+K40*0.06%*K36*0.3%+K40*0.06%*K37*0.4%,K40*0.06%+K40*0.06%*$M$5+K40*0.06%*K38*0.25%)))) -> 0 | L41: =IF($C$40="Inactif",0,IF(L13="Rocta",L40*0.06%+L40*0.06%*$M$4,IF(L13="Humains",L40*0.06%+L40*0.06%*$M$2+L40*0.06%*L35*0.5%,IF(L13="Méca",L40*0.06%+L40*0.06%*$M$3+L40*0.06%*L36*0.3%+L40*0.06%*L37*0.4%,L40*0.06%+L40*0.06%*$M$5+L40*0.06%*L38*0.25%)))) -> 0 | ... X41: =IF($C$40="Inactif",0,IF(X13="Rocta",X40*0.06%+X40*0.06%*$M$4,IF(X13="Humains",X40*0.06%+X40*0.06%*$M$2+X40*0.06%*X35*0.5%,IF(X13="Méca",X40*0.06%+X40*0.06%*$M$3+X40*0.06%*X36*0.3%+X40*0.06%*X37*0.4%,X40*0.06%+X40*0.06%*$M$5+X40*0.06%*X38*0.25%)))) -> 0 | Y41: =SUM(E41:X41) -> 0.01368
B42: ● | C42: Actif | D42: 2-2 Humain (Trio) (0,06%) | E42: 16 | Y42: =SUM(E42:X42) -> 16
B43: ● | D43: Bonus Mét + Cri + Deut | E43: =IF($C$42="Inactif",0,IF(E13="Rocta",E42*0.06%+E42*0.06%*$M$4,IF(E13="Humains",E42*0.06%+E42*0.06%*$M$2+E42*0.06%*E35*0.5%,IF(E13="Méca",E42*0.06%+E42*0.06%*$M$3+E42*0.06%*E36*0.3%+E42*0.06%*E37*0.4%,E42*0.06%+E42*0.06%*$M$5+E42*0.06%*E38*0.25%)))) -> 0.01152 | F43: =IF($C$42="Inactif",0,IF(F13="Rocta",F42*0.06%+F42*0.06%*$M$4,IF(F13="Humains",F42*0.06%+F42*0.06%*$M$2+F42*0.06%*F35*0.5%,IF(F13="Méca",F42*0.06%+F42*0.06%*$M$3+F42*0.06%*F36*0.3%+F42*0.06%*F37*0.4%,F42*0.06%+F42*0.06%*$M$5+F42*0.06%*F38*0.25%)))) -> 0 | G43: =IF($C$42="Inactif",0,IF(G13="Rocta",G42*0.06%+G42*0.06%*$M$4,IF(G13="Humains",G42*0.06%+G42*0.06%*$M$2+G42*0.06%*G35*0.5%,IF(G13="Méca",G42*0.06%+G42*0.06%*$M$3+G42*0.06%*G36*0.3%+G42*0.06%*G37*0.4%,G42*0.06%+G42*0.06%*$M$5+G42*0.06%*G38*0.25%)))) -> 0 | H43: =IF($C$42="Inactif",0,IF(H13="Rocta",H42*0.06%+H42*0.06%*$M$4,IF(H13="Humains",H42*0.06%+H42*0.06%*$M$2+H42*0.06%*H35*0.5%,IF(H13="Méca",H42*0.06%+H42*0.06%*$M$3+H42*0.06%*H36*0.3%+H42*0.06%*H37*0.4%,H42*0.06%+H42*0.06%*$M$5+H42*0.06%*H38*0.25%)))) -> 0 | I43: =IF($C$42="Inactif",0,IF(I13="Rocta",I42*0.06%+I42*0.06%*$M$4,IF(I13="Humains",I42*0.06%+I42*0.06%*$M$2+I42*0.06%*I35*0.5%,IF(I13="Méca",I42*0.06%+I42*0.06%*$M$3+I42*0.06%*I36*0.3%+I42*0.06%*I37*0.4%,I42*0.06%+I42*0.06%*$M$5+I42*0.06%*I38*0.25%)))) -> 0 | J43: =IF($C$42="Inactif",0,IF(J13="Rocta",J42*0.06%+J42*0.06%*$M$4,IF(J13="Humains",J42*0.06%+J42*0.06%*$M$2+J42*0.06%*J35*0.5%,IF(J13="Méca",J42*0.06%+J42*0.06%*$M$3+J42*0.06%*J36*0.3%+J42*0.06%*J37*0.4%,J42*0.06%+J42*0.06%*$M$5+J42*0.06%*J38*0.25%)))) -> 0 | K43: =IF($C$42="Inactif",0,IF(K13="Rocta",K42*0.06%+K42*0.06%*$M$4,IF(K13="Humains",K42*0.06%+K42*0.06%*$M$2+K42*0.06%*K35*0.5%,IF(K13="Méca",K42*0.06%+K42*0.06%*$M$3+K42*0.06%*K36*0.3%+K42*0.06%*K37*0.4%,K42*0.06%+K42*0.06%*$M$5+K42*0.06%*K38*0.25%)))) -> 0 | L43: =IF($C$42="Inactif",0,IF(L13="Rocta",L42*0.06%+L42*0.06%*$M$4,IF(L13="Humains",L42*0.06%+L42*0.06%*$M$2+L42*0.06%*L35*0.5%,IF(L13="Méca",L42*0.06%+L42*0.06%*$M$3+L42*0.06%*L36*0.3%+L42*0.06%*L37*0.4%,L42*0.06%+L42*0.06%*$M$5+L42*0.06%*L38*0.25%)))) -> 0 | ... X43: =IF($C$42="Inactif",0,IF(X13="Rocta",X42*0.06%+X42*0.06%*$M$4,IF(X13="Humains",X42*0.06%+X42*0.06%*$M$2+X42*0.06%*X35*0.5%,IF(X13="Méca",X42*0.06%+X42*0.06%*$M$3+X42*0.06%*X36*0.3%+X42*0.06%*X37*0.4%,X42*0.06%+X42*0.06%*$M$5+X42*0.06%*X38*0.25%)))) -> 0 | Y43: =SUM(E43:X43) -> 0.01152
B44: ● | C44: Actif | D44: 1-1 Méca (Deut) (0,08%) | E44: 20 | Y44: =SUM(E44:X44) -> 20
B45: ● | D45: Bonus Deut | E45: =IF($C$44="Inactif",0,IF(E13="Rocta",E44*0.08%+E44*0.08%*$M$4,IF(E13="Humains",E44*0.08%+E44*0.08%*$M$2+E44*0.08%*E35*0.5%,IF(E13="Méca",E44*0.08%+E44*0.08%*$M$3+E44*0.08%*E36*0.3%+E44*0.08%*E37*0.4%,E44*0.08%+E44*0.08%*$M$5+E44*0.08%*E38*0.25%)))) -> 0.0192 | F45: =IF($C$44="Inactif",0,IF(F13="Rocta",F44*0.08%+F44*0.08%*$M$4,IF(F13="Humains",F44*0.08%+F44*0.08%*$M$2+F44*0.08%*F35*0.5%,IF(F13="Méca",F44*0.08%+F44*0.08%*$M$3+F44*0.08%*F36*0.3%+F44*0.08%*F37*0.4%,F44*0.08%+F44*0.08%*$M$5+F44*0.08%*F38*0.25%)))) -> 0 | G45: =IF($C$44="Inactif",0,IF(G13="Rocta",G44*0.08%+G44*0.08%*$M$4,IF(G13="Humains",G44*0.08%+G44*0.08%*$M$2+G44*0.08%*G35*0.5%,IF(G13="Méca",G44*0.08%+G44*0.08%*$M$3+G44*0.08%*G36*0.3%+G44*0.08%*G37*0.4%,G44*0.08%+G44*0.08%*$M$5+G44*0.08%*G38*0.25%)))) -> 0 | H45: =IF($C$44="Inactif",0,IF(H13="Rocta",H44*0.08%+H44*0.08%*$M$4,IF(H13="Humains",H44*0.08%+H44*0.08%*$M$2+H44*0.08%*H35*0.5%,IF(H13="Méca",H44*0.08%+H44*0.08%*$M$3+H44*0.08%*H36*0.3%+H44*0.08%*H37*0.4%,H44*0.08%+H44*0.08%*$M$5+H44*0.08%*H38*0.25%)))) -> 0 | I45: =IF($C$44="Inactif",0,IF(I13="Rocta",I44*0.08%+I44*0.08%*$M$4,IF(I13="Humains",I44*0.08%+I44*0.08%*$M$2+I44*0.08%*I35*0.5%,IF(I13="Méca",I44*0.08%+I44*0.08%*$M$3+I44*0.08%*I36*0.3%+I44*0.08%*I37*0.4%,I44*0.08%+I44*0.08%*$M$5+I44*0.08%*I38*0.25%)))) -> 0 | J45: =IF($C$44="Inactif",0,IF(J13="Rocta",J44*0.08%+J44*0.08%*$M$4,IF(J13="Humains",J44*0.08%+J44*0.08%*$M$2+J44*0.08%*J35*0.5%,IF(J13="Méca",J44*0.08%+J44*0.08%*$M$3+J44*0.08%*J36*0.3%+J44*0.08%*J37*0.4%,J44*0.08%+J44*0.08%*$M$5+J44*0.08%*J38*0.25%)))) -> 0 | K45: =IF($C$44="Inactif",0,IF(K13="Rocta",K44*0.08%+K44*0.08%*$M$4,IF(K13="Humains",K44*0.08%+K44*0.08%*$M$2+K44*0.08%*K35*0.5%,IF(K13="Méca",K44*0.08%+K44*0.08%*$M$3+K44*0.08%*K36*0.3%+K44*0.08%*K37*0.4%,K44*0.08%+K44*0.08%*$M$5+K44*0.08%*K38*0.25%)))) -> 0 | L45: =IF($C$44="Inactif",0,IF(L13="Rocta",L44*0.08%+L44*0.08%*$M$4,IF(L13="Humains",L44*0.08%+L44*0.08%*$M$2+L44*0.08%*L35*0.5%,IF(L13="Méca",L44*0.08%+L44*0.08%*$M$3+L44*0.08%*L36*0.3%+L44*0.08%*L37*0.4%,L44*0.08%+L44*0.08%*$M$5+L44*0.08%*L38*0.25%)))) -> 0 | ... X45: =IF($C$44="Inactif",0,IF(X13="Rocta",X44*0.08%+X44*0.08%*$M$4,IF(X13="Humains",X44*0.08%+X44*0.08%*$M$2+X44*0.08%*X35*0.5%,IF(X13="Méca",X44*0.08%+X44*0.08%*$M$3+X44*0.08%*X36*0.3%+X44*0.08%*X37*0.4%,X44*0.08%+X44*0.08%*$M$5+X44*0.08%*X38*0.25%)))) -> 0 | Y45: =SUM(E45:X45) -> 0.0192
...

Sheet 3. Comparaison
K2: Bonus Humain ● | M2: ='2. Simulation'!M2-'1. Base'!M2 -> 0 | P2: Bonus Métal Global Tech FDV ● | T2: =Y41+Y43+Y47+Y49+Y57+Y59+Y69 -> 0.00722
D3: Classe choisie ● | E3: =IF('2. Simulation'!E3='1. Base'!E3,"RAS","Changement de Classe") -> RAS | K3: Bonus Méca ● | M3: ='2. Simulation'!M3-'1. Base'!M3 -> 0 | P3: Bonus Cristal Global tech FDV ● | T3: =Y41+Y43+Y47+Y49+Y69 -> 0.00474
K4: Bonus Rocta ● | M4: ='2. Simulation'!M4-'1. Base'!M4 -> 0 | P4: Bonus Deut Global Tech FDV ● | T4: =Y41+Y43+Y45+Y47+Y49+Y53+Y69 -> 0.00786
K5: Bonus Kaelesh ● | M5: ='2. Simulation'!M5-'1. Base'!M5 -> 0 | P5: Bonus Collecteur ● | T5: =Y65 -> 0
B6: ● | C6: Remplir la ligne
B7: ● | C7: Ne pas toucher la ligne (formules)
D8: N° de Planète | E8: Planète 1 | F8: Planète 2 | G8: Planète 3 | H8: Planète 4 | I8: Planète 5 | J8: Planète 6 | K8: Planète 7 | L8: Planète 8 | M8: Planète 9 | N8: Planète 10 | O8: Planète 11 | P8: Planète 12 | Q8: Planète 13 | R8: Planète 14 | S8: Planète 15 | T8: Planète 16 | U8: Planète 17 | V8: Planète 18 | W8: Planète 19 | X8: Planète 20 | Y8: Total
B9: ● | C9: Infos de Base | D9: Nom de Planète | E9: ='1. Base'!E9 -> Birgitte | F9: ='1. Base'!F9 -> 0 | G9: ='1. Base'!G9 -> 0 | H9: ='1. Base'!H9 -> 0 | I9: ='1. Base'!I9 -> 0 | J9: ='1. Base'!J9 -> 0 | K9: ='1. Base'!K9 -> 0 | L9: ='1. Base'!L9 -> 0 | ... X9: ='1. Base'!X9 -> 0
B10: ● | D10: Coordonnées de la Planète | E10: ='1. Base'!E10 -> 3:198:15 | F10: ='1. Base'!F10 -> 0 | G10: ='1. Base'!G10 -> 0 | H10: ='1. Base'!H10 -> 0 | I10: ='1. Base'!I10 -> 0 | J10: ='1. Base'!J10 -> 0 | K10: ='1. Base'!K10 -> 0 | L10: ='1. Base'!L10 -> 0 | ... X10: ='1. Base'!X10 -> 0
B11: ● | D11: Position de la Planète | E11: ='1. Base'!E11 -> 15 | F11: ='1. Base'!F11 -> 0 | G11: ='1. Base'!G11 -> 0 | H11: ='1. Base'!H11 -> 0 | I11: ='1. Base'!I11 -> 0 | J11: ='1. Base'!J11 -> 0 | K11: ='1. Base'!K11 -> 0 | L11: ='1. Base'!L11 -> 0 | ... X11: ='1. Base'!X11 -> 0
B12: ● | D12: Température Max
B13: ● | D13: Race Choisie | E13: =IF('2. Simulation'!E13='1. Base'!E13,"RAS","SWITCH") -> SWITCH | F13: =IF('2. Simulation'!F13='1. Base'!F13,"RAS","SWITCH") -> RAS | G13: =IF('2. Simulation'!G13='1. Base'!G13,"RAS","SWITCH") -> RAS | H13: =IF('2. Simulation'!H13='1. Base'!H13,"RAS","SWITCH") -> RAS | I13: =IF('2. Simulation'!I13='1. Base'!I13,"RAS","SWITCH") -> RAS | J13: =IF('2. Simulation'!J13='1. Base'!J13,"RAS","SWITCH") -> RAS | K13: =IF('2. Simulation'!K13='1. Base'!K13,"RAS","SWITCH") -> RAS | L13: =IF('2. Simulation'!L13='1. Base'!L13,"RAS","SWITCH") -> RAS | ... X13: =IF('2. Simulation'!X13='1. Base'!X13,"RAS","SWITCH") -> RAS
B14: ● | D14: Nb Max de foreuses
B15: ● | D15: Alerte Foreuse
B17: ● | C17: Infos Mines & Bats Prod FDV | D17: Mine de Métal | E17: ='2. Simulation'!E17-'1. Base'!E17 -> 0 | F17: ='2. Simulation'!F17-'1. Base'!F17 -> 0 | G17: ='2. Simulation'!G17-'1. Base'!G17 -> 0 | H17: ='2. Simulation'!H17-'1. Base'!H17 -> 0 | I17: ='2. Simulation'!I17-'1. Base'!I17 -> 0 | J17: ='2. Simulation'!J17-'1. Base'!J17 -> 0 | K17: ='2. Simulation'!K17-'1. Base'!K17 -> 0 | L17: ='2. Simulation'!L17-'1. Base'!L17 -> 0 | ... X17: ='2. Simulation'!X17-'1. Base'!X17 -> 0 | Y17: =SUM(E17:X17) -> 0
B18: ● | D18: Mine de Cristal | E18: ='2. Simulation'!E18-'1. Base'!E18 -> 0 | F18: ='2. Simulation'!F18-'1. Base'!F18 -> 0 | G18: ='2. Simulation'!G18-'1. Base'!G18 -> 0 | H18: ='2. Simulation'!H18-'1. Base'!H18 -> 0 | I18: ='2. Simulation'!I18-'1. Base'!I18 -> 0 | J18: ='2. Simulation'!J18-'1. Base'!J18 -> 0 | K18: ='2. Simulation'!K18-'1. Base'!K18 -> 0 | L18: ='2. Simulation'!L18-'1. Base'!L18 -> 0 | ... X18: ='2. Simulation'!X18-'1. Base'!X18 -> 0 | Y18: =SUM(E18:X18) -> 0
B19: ● | D19: Mine de Deut | E19: ='2. Simulation'!E19-'1. Base'!E19 -> 0 | F19: ='2. Simulation'!F19-'1. Base'!F19 -> 0 | G19: ='2. Simulation'!G19-'1. Base'!G19 -> 0 | H19: ='2. Simulation'!H19-'1. Base'!H19 -> 0 | I19: ='2. Simulation'!I19-'1. Base'!I19 -> 0 | J19: ='2. Simulation'!J19-'1. Base'!J19 -> 0 | K19: ='2. Simulation'!K19-'1. Base'!K19 -> 0 | L19: ='2. Simulation'!L19-'1. Base'!L19 -> 0 | ... X19: ='2. Simulation'!X19-'1. Base'!X19 -> 0 | Y19: =SUM(E19:X19) -> 0
B20: ● | D20: Centrale Fusion | E20: ='2. Simulation'!E20-'1. Base'!E20 -> 0 | F20: ='2. Simulation'!F20-'1. Base'!F20 -> 0 | G20: ='2. Simulation'!G20-'1. Base'!G20 -> 0 | H20: ='2. Simulation'!H20-'1. Base'!H20 -> 0 | I20: ='2. Simulation'!I20-'1. Base'!I20 -> 0 | J20: ='2. Simulation'!J20-'1. Base'!J20 -> 0 | K20: ='2. Simulation'!K20-'1. Base'!K20 -> 0 | L20: ='2. Simulation'!L20-'1. Base'!L20 -> 0 | ... X20: ='2. Simulation'!X20-'1. Base'!X20 -> 0 | Y20: =SUM(E20:X20) -> 0
B21: ● | D21: Fusion Magmatique (Rocta) (Mét 2%) | E21: ='2. Simulation'!E21-'1. Base'!E21 -> 0 | F21: ='2. Simulation'!F21-'1. Base'!F21 -> 0 | G21: ='2. Simulation'!G21-'1. Base'!G21 -> 0 | H21: ='2. Simulation'!H21-'1. Base'!H21 -> 0 | I21: ='2. Simulation'!I21-'1. Base'!I21 -> 0 | J21: ='2. Simulation'!J21-'1. Base'!J21 -> 0 | K21: ='2. Simulation'!K21-'1. Base'!K21 -> 0 | L21: ='2. Simulation'!L21-'1. Base'!L21 -> 0 | ... X21: ='2. Simulation'!X21-'1. Base'!X21 -> 0 | Y21: =SUM(E21:X21) -> 0
B22: ● | D22: Raffinerie de Cristaux (Rocta) (Cri 2%) | E22: ='2. Simulation'!E22-'1. Base'!E22 -> 0 | F22: ='2. Simulation'!F22-'1. Base'!F22 -> 0 | G22: ='2. Simulation'!G22-'1. Base'!G22 -> 0 | H22: ='2. Simulation'!H22-'1. Base'!H22 -> 0 | I22: ='2. Simulation'!I22-'1. Base'!I22 -> 0 | J22: ='2. Simulation'!J22-'1. Base'!J22 -> 0 | K22: ='2. Simulation'!K22-'1. Base'!K22 -> 0 | L22: ='2. Simulation'!L22-'1. Base'!L22 -> 0 | ... X22: ='2. Simulation'!X22-'1. Base'!X22 -> 0 | Y22: =SUM(E22:X22) -> 0
B23: ● | D23: Synto de Deut (Rocta) (Deut 2%) | E23: ='2. Simulation'!E23-'1. Base'!E23 -> 0 | F23: ='2. Simulation'!F23-'1. Base'!F23 -> 0 | G23: ='2. Simulation'!G23-'1. Base'!G23 -> 0 | H23: ='2. Simulation'!H23-'1. Base'!H23 -> 0 | I23: ='2. Simulation'!I23-'1. Base'!I23 -> 0 | J23: ='2. Simulation'!J23-'1. Base'!J23 -> 0 | K23: ='2. Simulation'!K23-'1. Base'!K23 -> 0 | L23: ='2. Simulation'!L23-'1. Base'!L23 -> 0 | ... X23: ='2. Simulation'!X23-'1. Base'!X23 -> 0 | Y23: =SUM(E23:X23) -> 0
B24: ● | D24: Fusion à haute énergie (Humains) (Mét 1,5%) | E24: ='2. Simulation'!E24-'1. Base'!E24 -> 0 | F24: ='2. Simulation'!F24-'1. Base'!F24 -> 0 | G24: ='2. Simulation'!G24-'1. Base'!G24 -> 0 | H24: ='2. Simulation'!H24-'1. Base'!H24 -> 0 | I24: ='2. Simulation'!I24-'1. Base'!I24 -> 0 | J24: ='2. Simulation'!J24-'1. Base'!J24 -> 0 | K24: ='2. Simulation'!K24-'1. Base'!K24 -> 0 | L24: ='2. Simulation'!L24-'1. Base'!L24 -> 0 | ... X24: ='2. Simulation'!X24-'1. Base'!X24 -> 0 | Y24: =SUM(E24:X24) -> 0
B25: ● | D25: Extraction par fusion (Humains) (Cri 1,5%) | E25: ='2. Simulation'!E25-'1. Base'!E25 -> 0 | F25: ='2. Simulation'!F25-'1. Base'!F25 -> 0 | G25: ='2. Simulation'!G25-'1. Base'!G25 -> 0 | H25: ='2. Simulation'!H25-'1. Base'!H25 -> 0 | I25: ='2. Simulation'!I25-'1. Base'!I25 -> 0 | J25: ='2. Simulation'!J25-'1. Base'!J25 -> 0 | K25: ='2. Simulation'!K25-'1. Base'!K25 -> 0 | L25: ='2. Simulation'!L25-'1. Base'!L25 -> 0 | ... X25: ='2. Simulation'!X25-'1. Base'!X25 -> 0 | Y25: =SUM(E25:X25) -> 0
B26: ● | D26: Extraction par fusion (Humains) (Deut 1%) | E26: ='2. Simulation'!E26-'1. Base'!E26 -> 0 | F26: ='2. Simulation'!F26-'1. Base'!F26 -> 0 | G26: ='2. Simulation'!G26-'1. Base'!G26 -> 0 | H26: ='2. Simulation'!H26-'1. Base'!H26 -> 0 | I26: ='2. Simulation'!I26-'1. Base'!I26 -> 0 | J26: ='2. Simulation'!J26-'1. Base'!J26 -> 0 | K26: ='2. Simulation'!K26-'1. Base'!K26 -> 0 | L26: ='2. Simulation'!L26-'1. Base'!L26 -> 0 | ... X26: ='2. Simulation'!X26-'1. Base'!X26 -> 0 | Y26: =SUM(E26:X26) -> 0
B27: ● | D27: Synthétiseur à haut rendement (Méca) (Deut 2%) | E27: ='2. Simulation'!E27-'1. Base'!E27 -> 15 | F27: ='2. Simulation'!F27-'1. Base'!F27 -> 0 | G27: ='2. Simulation'!G27-'1. Base'!G27 -> 0 | H27: ='2. Simulation'!H27-'1. Base'!H27 -> 0 | I27: ='2. Simulation'!I27-'1. Base'!I27 -> 0 | J27: ='2. Simulation'!J27-'1. Base'!J27 -> 0 | K27: ='2. Simulation'!K27-'1. Base'!K27 -> 0 | L27: ='2. Simulation'!L27-'1. Base'!L27 -> 0 | ... X27: ='2. Simulation'!X27-'1. Base'!X27 -> 0 | Y27: =SUM(E27:X27) -> 15
B28: ● | D28: Nombre de Foreuses | E28: ='2. Simulation'!E28-'1. Base'!E28 -> 0 | F28: ='2. Simulation'!F28-'1. Base'!F28 -> 0 | G28: ='2. Simulation'!G28-'1. Base'!G28 -> 0 | H28: ='2. Simulation'!H28-'1. Base'!H28 -> 0 | I28: ='2. Simulation'!I28-'1. Base'!I28 -> 0 | J28: ='2. Simulation'!J28-'1. Base'!J28 -> 0 | K28: ='2. Simulation'!K28-'1. Base'!K28 -> 0 | L28: ='2. Simulation'!L28-'1. Base'!L28 -> 0 | ... X28: ='2. Simulation'!X28-'1. Base'!X28 -> 0 | Y28: =SUM(E28:X28) -> 0
B29: ● | D29: Tech Plasma | E29: ='2. Simulation'!E29-'1. Base'!E29 -> 0 | F29: ='2. Simulation'!F29-'1. Base'!F29 -> 0 | G29: ='2. Simulation'!G29-'1. Base'!G29 -> 0 | H29: ='2. Simulation'!H29-'1. Base'!H29 -> 0 | I29: ='2. Simulation'!I29-'1. Base'!I29 -> 0 | J29: ='2. Simulation'!J29-'1. Base'!J29 -> 0 | K29: ='2. Simulation'!K29-'1. Base'!K29 -> 0 | L29: ='2. Simulation'!L29-'1. Base'!L29 -> 0 | ... X29: ='2. Simulation'!X29-'1. Base'!X29 -> 0 | Y29: =AVERAGE(E29:X29) -> 0
B31: ● | C31: Objets | D31: % Bonus Objet Mét | E31: ='2. Simulation'!E31-'1. Base'!E31 -> 0 | F31: ='2. Simulation'!F31-'1. Base'!F31 -> 0 | G31: ='2. Simulation'!G31-'1. Base'!G31 -> 0 | H31: ='2. Simulation'!H31-'1. Base'!H31 -> 0 | I31: ='2. Simulation'!I31-'1. Base'!I31 -> 0 | J31: ='2. Simulation'!J31-'1. Base'!J31 -> 0 | K31: ='2. Simulation'!K31-'1. Base'!K31 -> 0 | L31: ='2. Simulation'!L31-'1. Base'!L31 -> 0 | ... X31: ='2. Simulation'!X31-'1. Base'!X31 -> 0
B32: ● | D32: % Bonus Objet Cri | E32: ='2. Simulation'!E32-'1. Base'!E32 -> 0 | F32: ='2. Simulation'!F32-'1. Base'!F32 -> 0 | G32: ='2. Simulation'!G32-'1. Base'!G32 -> 0 | H32: ='2. Simulation'!H32-'1. Base'!H32 -> 0 | I32: ='2. Simulation'!I32-'1. Base'!I32 -> 0 | J32: ='2. Simulation'!J32-'1. Base'!J32 -> 0 | K32: ='2. Simulation'!K32-'1. Base'!K32 -> 0 | L32: ='2. Simulation'!L32-'1. Base'!L32 -> 0 | ... X32: ='2. Simulation'!X32-'1. Base'!X32 -> 0
B33: ● | D33: % Bonus Objet Deut | E33: ='2. Simulation'!E33-'1. Base'!E33 -> 0 | F33: ='2. Simulation'!F33-'1. Base'!F33 -> 0 | G33: ='2. Simulation'!G33-'1. Base'!G33 -> 0 | H33: ='2. Simulation'!H33-'1. Base'!H33 -> 0 | I33: ='2. Simulation'!I33-'1. Base'!I33 -> 0 | J33: ='2. Simulation'!J33-'1. Base'!J33 -> 0 | K33: ='2. Simulation'!K33-'1. Base'!K33 -> 0 | L33: ='2. Simulation'!L33-'1. Base'!L33 -> 0 | ... X33: ='2. Simulation'!X33-'1. Base'!X33 -> 0
B35: ● | C35: Bat Boost Tech FDV | D35: Métro (Humain) (0,5%) | E35: ='2. Simulation'!E35-'1. Base'!E35 -> 0 | F35: ='2. Simulation'!F35-'1. Base'!F35 -> 0 | G35: ='2. Simulation'!G35-'1. Base'!G35 -> 0 | H35: ='2. Simulation'!H35-'1. Base'!H35 -> 0 | I35: ='2. Simulation'!I35-'1. Base'!I35 -> 0 | J35: ='2. Simulation'!J35-'1. Base'!J35 -> 0 | K35: ='2. Simulation'!K35-'1. Base'!K35 -> 0 | L35: ='2. Simulation'!L35-'1. Base'!L35 -> 0 | ... X35: ='2. Simulation'!X35-'1. Base'!X35 -> 0 | Y35: =SUM(E35:X35) -> 0
B36: ● | D36: Transfo Hyper (Méca) (0,3%) | E36: ='2. Simulation'!E36-'1. Base'!E36 -> 17 | F36: ='2. Simulation'!F36-'1. Base'!F36 -> 0 | G36: ='2. Simulation'!G36-'1. Base'!G36 -> 0 | H36: ='2. Simulation'!H36-'1. Base'!H36 -> 0 | I36: ='2. Simulation'!I36-'1. Base'!I36 -> 0 | J36: ='2. Simulation'!J36-'1. Base'!J36 -> 0 | K36: ='2. Simulation'!K36-'1. Base'!K36 -> 0 | L36: ='2. Simulation'!L36-'1. Base'!L36 -> 0 | ... X36: ='2. Simulation'!X36-'1. Base'!X36 -> 0 | Y36: =SUM(E36:X36) -> 17
B37: ● | D37: Prod de Puces (Méca) (0,4%) | E37: ='2. Simulation'!E37-'1. Base'!E37 -> 13 | F37: ='2. Simulation'!F37-'1. Base'!F37 -> 0 | G37: ='2. Simulation'!G37-'1. Base'!G37 -> 0 | H37: ='2. Simulation'!H37-'1. Base'!H37 -> 0 | I37: ='2. Simulation'!I37-'1. Base'!I37 -> 0 | J37: ='2. Simulation'!J37-'1. Base'!J37 -> 0 | K37: ='2. Simulation'!K37-'1. Base'!K37 -> 0 | L37: ='2. Simulation'!L37-'1. Base'!L37 -> 0 | ... X37: ='2. Simulation'!X37-'1. Base'!X37 -> 0 | Y37: =SUM(E37:X37) -> 13
B38: ● | D38: Labo de Clonage (Kaelesh) (0,25%) | E38: ='2. Simulation'!E38-'1. Base'!E38 -> 0 | F38: ='2. Simulation'!F38-'1. Base'!F38 -> 0 | G38: ='2. Simulation'!G38-'1. Base'!G38 -> 0 | H38: ='2. Simulation'!H38-'1. Base'!H38 -> 0 | I38: ='2. Simulation'!I38-'1. Base'!I38 -> 0 | J38: ='2. Simulation'!J38-'1. Base'!J38 -> 0 | K38: ='2. Simulation'!K38-'1. Base'!K38 -> 0 | L38: ='2. Simulation'!L38-'1. Base'!L38 -> 0 | ... X38: ='2. Simulation'!X38-'1. Base'!X38 -> 0 | Y38: =SUM(E38:X38) -> 0
B40: ● | C40: =IF('2. Simulation'!C40='1. Base'!C40,"RAS","SWITCH") -> RAS | D40: 1-2 Humain (Trio) (0,06%) | E40: ='2. Simulation'!E40-'1. Base'!E40 -> 0 | F40: ='2. Simulation'!F40-'1. Base'!F40 -> 0 | G40: ='2. Simulation'!G40-'1. Base'!G40 -> 0 | H40: ='2. Simulation'!H40-'1. Base'!H40 -> 0 | I40: ='2. Simulation'!I40-'1. Base'!I40 -> 0 | J40: ='2. Simulation'!J40-'1. Base'!J40 -> 0 | K40: ='2. Simulation'!K40-'1. Base'!K40 -> 0 | L40: ='2. Simulation'!L40-'1. Base'!L40 -> 0 | ... X40: ='2. Simulation'!X40-'1. Base'!X40 -> 0 | Y40: =SUM(E40:X40) -> 0
B41: ● | D41: Bonus Mét + Cri + Deut | E41: ='2. Simulation'!E41-'1. Base'!E41 -> 0.00114 | F41: ='2. Simulation'!F41-'1. Base'!F41 -> 0 | G41: ='2. Simulation'!G41-'1. Base'!G41 -> 0 | H41: ='2. Simulation'!H41-'1. Base'!H41 -> 0 | I41: ='2. Simulation'!I41-'1. Base'!I41 -> 0 | J41: ='2. Simulation'!J41-'1. Base'!J41 -> 0 | K41: ='2. Simulation'!K41-'1. Base'!K41 -> 0 | L41: ='2. Simulation'!L41-'1. Base'!L41 -> 0 | ... X41: ='2. Simulation'!X41-'1. Base'!X41 -> 0 | Y41: =SUM(E41:U41) -> 0.00114
B42: ● | C42: =IF('2. Simulation'!C42='1. Base'!C42,"RAS","SWITCH") -> RAS | D42: 2-2 Humain (Trio) (0,06%) | E42: ='2. Simulation'!E42-'1. Base'!E42 -> 0 | F42: ='2. Simulation'!F42-'1. Base'!F42 -> 0 | G42: ='2. Simulation'!G42-'1. Base'!G42 -> 0 | H42: ='2. Simulation'!H42-'1. Base'!H42 -> 0 | I42: ='2. Simulation'!I42-'1. Base'!I42 -> 0 | J42: ='2. Simulation'!J42-'1. Base'!J42 -> 0 | K42: ='2. Simulation'!K42-'1. Base'!K42 -> 0 | L42: ='2. Simulation'!L42-'1. Base'!L42 -> 0 | ... X42: ='2. Simulation'!X42-'1. Base'!X42 -> 0 | Y42: =SUM(E42:X42) -> 0
B43: ● | D43: Bonus Mét + Cri + Deut | E43: ='2. Simulation'!E43-'1. Base'!E43 -> 0.00096 | F43: ='2. Simulation'!F43-'1. Base'!F43 -> 0 | G43: ='2. Simulation'!G43-'1. Base'!G43 -> 0 | H43: ='2. Simulation'!H43-'1. Base'!H43 -> 0 | I43: ='2. Simulation'!I43-'1. Base'!I43 -> 0 | J43: ='2. Simulation'!J43-'1. Base'!J43 -> 0 | K43: ='2. Simulation'!K43-'1. Base'!K43 -> 0 | L43: ='2. Simulation'!L43-'1. Base'!L43 -> 0 | ... X43: ='2. Simulation'!X43-'1. Base'!X43 -> 0 | Y43: =SUM(E43:U43) -> 0.00096
B44: ● | C44: =IF('2. Simulation'!C44='1. Base'!C44,"RAS","SWITCH") -> RAS | D44: 1-1 Méca (Deut) (0,08%) | E44: ='2. Simulation'!E44-'1. Base'!E44 -> 0 | F44: ='2. Simulation'!F44-'1. Base'!F44 -> 0 | G44: ='2. Simulation'!G44-'1. Base'!G44 -> 0 | H44: ='2. Simulation'!H44-'1. Base'!H44 -> 0 | I44: ='2. Simulation'!I44-'1. Base'!I44 -> 0 | J44: ='2. Simulation'!J44-'1. Base'!J44 -> 0 | K44: ='2. Simulation'!K44-'1. Base'!K44 -> 0 | L44: ='2. Simulation'!L44-'1. Base'!L44 -> 0 | ... X44: ='2. Simulation'!X44-'1. Base'!X44 -> 0 | Y44: =SUM(E44:X44) -> 0
B45: ● | D45: Bonus Deut | E45: ='2. Simulation'!E45-'1. Base'!E45 -> 0.0016 | F45: ='2. Simulation'!F45-'1. Base'!F45 -> 0 | G45: ='2. Simulation'!G45-'1. Base'!G45 -> 0 | H45: ='2. Simulation'!H45-'1. Base'!H45 -> 0 | I45: ='2. Simulation'!I45-'1. Base'!I45 -> 0 | J45: ='2. Simulation'!J45-'1. Base'!J45 -> 0 | K45: ='2. Simulation'!K45-'1. Base'!K45 -> 0 | L45: ='2. Simulation'!L45-'1. Base'!L45 -> 0 | ... X45: ='2. Simulation'!X45-'1. Base'!X45 -> 0 | Y45: =SUM(E45:U45) -> 0.0016
...

Sheet 4. Synthèse
C1: Bonus Tech FDV
C2: ● | D2: Bonus Métal Global | E2: ='3. Comparaison'!Y71 -> 0.00722 | F2: M
C3: ● | D3: Bonus Cristal Global | E3: ='3. Comparaison'!Y72 -> 0.00474 | F3: C
C4: ● | D4: Bonus Deut Global | E4: ='3. Comparaison'!Y73 -> 0.00786 | F4: D
B6: Détail Prod | C6: Synthèse Gain/Perte
B8: ● | C8: Base | D8: Prod. Métal (/h) | E8: ='3. Comparaison'!Y78 -> 0 | F8: M
B9: ● | C9: Base | D9: Prod. Cristal (/h) | E9: ='3. Comparaison'!Y79 -> 0 | F9: C
B10: ● | C10: Base | D10: Prod. Deut (/h) | E10: ='3. Comparaison'!Y80 -> 0 | F10: D
B11: ● | C11: Bat FDV | D11: Prod. Métal (/h) | E11: ='3. Comparaison'!Y82+'3. Comparaison'!Y85 -> -642642.16 | F11: M
B12: ● | C12: Bat FDV | D12: Prod. Cristal (/h) | E12: ='3. Comparaison'!Y83+'3. Comparaison'!Y86 -> -83441.609 | F12: C
B13: ● | C13: Bat FDV | D13: Prod. Deut (/h) | E13: ='3. Comparaison'!Y84+'3. Comparaison'!Y87+'3. Comparaison'!Y88 -> -20308.132 | F13: D
B14: ● | C14: Tech FDV | D14: Prod. Métal (/h) | E14: ='3. Comparaison'!Y136 -> 10086.688 | F14: M
B15: ● | C15: Tech FDV | D15: Prod. Cristal (/h) | E15: ='3. Comparaison'!Y137 -> 1521.2047 | F15: C
B16: ● | C16: Tech FDV | D16: Prod. Deut (/h) | E16: ='3. Comparaison'!Y138 -> 3990.548 | F16: D
B18: Totaux Prod | C18: Synthèse Gain/Perte
B19: /j
B20: ● | C20: Total Prod | D20: Total Prod Mét (/j) | E20: ='3. Comparaison'!Y148 -> -15181331 | F20: M
B21: ● | C21: Total Prod | D21: Total Prod Cri (/j) | E21: ='3. Comparaison'!Y149 -> -1966089.7 | F21: C
B22: ● | C22: Total Prod | D22: Total Prod Deut (/j) | E22: ='3. Comparaison'!Y150 -> -391622.02 | F22: D
B23: ● | C23: Total Prod | D23: Total Points Produits (/j) | E23: ='3. Comparaison'!Y151 -> -17539043 | F23: GLO
B24: ● | C24: Total Prod | D24: Total USM Produits (/j) | E24: ='3. Comparaison'!Y152 -> -19305332 | F24: USM
B25: /mois
B26: ● | C26: Total Prod | D26: Total Prod Mét (/mois) | E26: ='3. Comparaison'!Y160 -> -4.7062127e+08 | F26: M
B27: ● | C27: Total Prod | D27: Total Prod Cri (/mois) | E27: ='3. Comparaison'!Y161 -> -60948781 | F27: C
B28: ● | C28: Total Prod | D28: Total Prod Deut (/mois) | E28: ='3. Comparaison'!Y162 -> -12140283 | F28: D
B29: ● | C29: Total Prod | D29: Total Points Produits (/mois) | E29: ='3. Comparaison'!Y163 -> -5.4371033e+08 | F29: GLO
B30: ● | C30: Total Prod | D30: Total USM Produits (/mois) | E30: ='3. Comparaison'!Y164 -> -5.9846529e+08 | F30: USM
B31: /an
B32: ● | C32: Total Prod | D32: Total Prod Mét (/an) | E32: ='3. Comparaison'!Y166 -> -5.5411859e+09 | F32: M
B33: ● | C33: Total Prod | D33: Total Prod Cri (/an) | E33: ='3. Comparaison'!Y167 -> -7.1762274e+08 | F33: C
B34: ● | C34: Total Prod | D34: Total Prod Deut (/an) | E34: ='3. Comparaison'!Y168 -> -1.4294204e+08 | F34: D
B35: ● | C35: Total Prod | D35: Total Points Produits (/an) | E35: ='3. Comparaison'!Y169 -> -6.4017507e+09 | F35: GLO
B36: ● | C36: Total Prod | D36: Total USM Produits (/an) | E36: ='3. Comparaison'!Y170 -> -7.0464461e+09 | F36: USM

Sheet Listes
A1: Liste Actif/Inactif | B1: Liste FDV | C1: Liste Classe | D1: Liste O/N
A2: Actif | B2: Rocta | C2: Explorateur | D2: Oui
A3: Inactif | B3: Humains | C3: Collecteur | D3: Non
B4: Méca | C4: Général
B5: Kaelesh
